<?xml version='1.0'?>

<robot name="myrobot" xmlns:xacro="http://www.ros.org/wiki/xacro">
<!-- xmlns:xacro="http://www.ros.org/wiki/xacro is also important dont know why -->

  <xacro:property name="chassis_x" value="0.4"/>
  <xacro:property name="chassis_y" value="0.2"/>
  <xacro:property name="chassis_z" value="0.1"/>
  <xacro:property name="chassis_mass" value="10"/>

  <xacro:property name="wheel_length" value="0.05"/>
  <xacro:property name="wheel_radius" value="0.1"/>
  <xacro:property name="wheel_mass" value="5"/>

  <xacro:property name="cameraRadius" value="0.02"/>
  <xacro:property name="cameraLength" value="0.05"/>
  <xacro:property name="cameraMass" value="0.1"/>

  <!-- Including File containing differential drive gazebo plugin -->
  <xacro:include filename="$(find rskbot_description)/urdf/rskbot.gazebo" />

  <!-- Including file containing materials information (colour) -->
  <xacro:include filename="$(find rskbot_description)/urdf/materials.xacro" />

  


<!-- ############################## Chassis  ####################################### -->
  <!-- Chassis consists of two links : main_body and caster (spherical wheel) -->

  <link name='chassis'>
    <pose>0 0 0.1 0 0 0</pose>

    <!-- Defining the inertia of whole chassis (main_body+caster) -->
    <inertial>
      <origin xyz="0 0 0.1" rpy=" 0 0 0"/>
      <mass value="${chassis_mass}"/>
      <inertia ixx="${0.0833333 * chassis_mass * (chassis_y*chassis_y + chassis_z*chassis_z)}" ixy="0.0" ixz="0.0"
        iyy="${0.0833333 * chassis_mass * (chassis_x*chassis_x + chassis_z*chassis_z)}" iyz="0.0"
        izz="${0.0833333 * chassis_mass * (chassis_x*chassis_x + chassis_y*chassis_y)}" />
    </inertial>

    <!-- ~~~~~~~~~~~~~~~~~~~~~~~~~~~~~~~~~~~~~~~~~~~ -->

    <!-- main_body's visual part and collision part is a cuboid  of size=".4 .2 .1" -->
    <visual name='chassis_main_body_visual'>   <!--Visual name must have initials of link name in order to have color in gazebo-->
      <origin xyz="0 0 0" rpy=" 0 0 0"/>
      <geometry>
        <box size="${chassis_x} ${chassis_y} ${chassis_z}"/>
      </geometry>
    </visual>

    <collision name='main_body_collision'>
      <geometry>
        <box size="${chassis_x} ${chassis_y} ${chassis_z}"/>
      </geometry>
    </collision>

    <!-- ~~~~~~~~~~~~~~~~~~~~~~~~~~~~~~~~~~~~~~~~~~~ -->

    <!-- caster wheel's visual part and collision part is a sphere  of radius="0.05" -->
    <visual name='caster_visual'>
      <origin xyz="-0.15 0 -0.05" rpy=" 0 0 0"/>
      <geometry>
        <sphere radius="0.05"/>
      </geometry>
    </visual>

    <collision name='caster_collision'>
      <origin xyz="-0.15 0 -0.05" rpy=" 0 0 0"/>
      <geometry>
        <sphere radius="0.05"/>
      </geometry>
      <surface>   <!--Defines the surface property-->
        <friction>
          <ode>
            <mu>0</mu>
            <mu2>0</mu2>
            <slip1>1.0</slip1>
            <slip2>1.0</slip2>
          </ode>
        </friction>
      </surface>
    </collision>
 
  </link>

  <!-- ############################## Left Wheel ####################################### -->


  <link name="left_wheel">
    <!--origin xyz="0.1 0.13 0.1" rpy="0 1.5707 1.5707"/-->
    <collision name="collision">
      <origin xyz="0 0 0" rpy="0 1.5707 1.5707"/>
      <geometry>
        <cylinder radius="${wheel_radius}" length="${wheel_length}"/>
      </geometry>
    </collision>
    <visual name="left_wheel_visual">
      <origin xyz="0 0 0" rpy="0 1.5707 1.5707"/>
      <geometry>
        <cylinder radius="${wheel_radius}" length="${wheel_length}"/>
      </geometry>
    </visual>
    <inertial>
      <origin xyz="0 0 0" rpy="0 1.5707 1.5707"/>
      <mass value="${wheel_mass}"/>
      <cylinder_inertia m="${wheel_mass}" r="${wheel_radius}" h="${wheel_length}"/>
      <inertia ixx="${0.0833333 * wheel_mass * (3 * wheel_radius * wheel_radius + wheel_length * wheel_length)}" ixy="0.0" ixz="0.0"
        iyy="${0.0833333 * wheel_mass * (3 * wheel_radius * wheel_radius + wheel_length * wheel_length)}" iyz="0.0"
        izz="${0.5 * wheel_mass * wheel_radius * wheel_radius}" />
    </inertial>
  </link>

  <!-- ############################## Right Wheel ####################################### -->


  <link name="right_wheel">
    <!--origin xyz="0.1 -0.13 0.1" rpy="0 1.5707 1.5707"/-->
    <collision name="collision">
      <origin xyz="0 0 0" rpy="0 1.5707 1.5707"/>
      <geometry>
        <cylinder radius="${wheel_radius}" length="${wheel_length}"/>
      </geometry>
    </collision>

    <visual name="right_wheel_visual">
      <origin xyz="0 0 0" rpy="0 1.5707 1.5707"/>
      <geometry>
        <cylinder radius="${wheel_radius}" length="${wheel_length}"/>
      </geometry>
    </visual>

    <inertial>
      <origin xyz="0 0 0" rpy="0 1.5707 1.5707"/>
      <mass value="5"/>
      <cylinder_inertia m="${wheel_mass}" r="${wheel_radius}" h="${wheel_length}"/>
      <inertia ixx="${0.0833333 * wheel_mass * (3 * wheel_radius * wheel_radius + wheel_length * wheel_length)}" ixy="0.0" ixz="0.0"
        iyy="${0.0833333 * wheel_mass * (3 * wheel_radius * wheel_radius + wheel_length * wheel_length)}" iyz="0.0"
        izz="${0.5 * wheel_mass * wheel_radius * wheel_radius}" />
    </inertial>
  </link>

  <!-- ############################ Chassis to Left Wheel Joint ########################## -->


  <joint type="continuous" name="left_wheel_hinge">
    <origin xyz="0.1 0.15 0" rpy="0 0 0"/>
    <child link="left_wheel"/>
    <parent link="chassis"/>
    <axis xyz="0 1 0" rpy="0 0 0"/>
    <limit effort="100" velocity="100"/>
    <joint_properties damping="0.0" friction="0.0"/>
  </joint>

  <!-- ############################ Chassis to Right Wheel Joint ########################## -->


  <joint type="continuous" name="right_wheel_hinge">
    <origin xyz="0.1 -0.15 0" rpy="0 0 0"/>
    <child link="right_wheel"/>
    <parent link="chassis"/>
    <axis xyz="0 1 0" rpy="0 0 0"/>
    <limit effort="100" velocity="100"/>
    <joint_properties damping="0.0" friction="0.0"/>
  </joint>

<!-- ############################## Left Camera  ####################################### -->

  <link name="left_camera">

    <inertial>
      <mass value="${cameraMass}" />
      <origin xyz="0 0 0" rpy="0 0 0"/>
      <inertia ixx="1e-6" ixy="0" ixz="0" iyy="1e-6" iyz="0" izz="1e-6" />
    </inertial>

    <visual>
      <origin xyz="0 0 0" rpy="0 1.57075 0"/>
      <geometry>
        <cylinder radius="${cameraRadius}" length="${cameraLength}"/>
      </geometry>
      <material name="green"/>
    </visual>

    <collision>
      <origin xyz="0 0 0" rpy="0 1.57075 0"/>
      <geometry>
        <cylinder radius="${cameraRadius}" length="${cameraLength}"/>
      </geometry>
    </collision>
    
  </link>

<!-- ############################## Chassis to Left Camera  ####################################### -->

  <joint name="left_camera_joint" type="fixed">
    <axis xyz="0 1 0" />
    <origin xyz="0.15 0.055 0.15" rpy="0 0 0"/>
    <parent link="chassis"/>
    <child link="left_camera"/>
  </joint>

<!-- ############################## Right Camera  ####################################### -->

  <link name="right_camera">

    <inertial>
      <mass value="${cameraMass}" />
      <origin xyz="0 0 0" rpy="0 0 0"/>
      <inertia ixx="1e-6" ixy="0" ixz="0" iyy="1e-6" iyz="0" izz="1e-6" />
    </inertial>

    <visual>
      <origin xyz="0 0 0" rpy="0 1.57075 0"/>
      <geometry>
        <cylinder radius="${cameraRadius}" length="${cameraLength}"/>
      </geometry>
      <material name="green"/>
    </visual>

    <collision>
      <origin xyz="0 0 0" rpy="0 1.57075 0"/>
      <geometry>
        <cylinder radius="${cameraRadius}" length="${cameraLength}"/>
      </geometry>
    </collision>
    
  </link>

<!-- ############################## Chassis to Right Camera  ####################################### -->

  <joint name="right_camera_joint" type="fixed">
    <axis xyz="0 1 0" />
    <origin xyz="0.15 -0.055 0.15" rpy="0 0 0"/>
    <parent link="chassis"/>
    <child link="right_camera"/>
  </joint>

<!-- ############################## Point cloud (dummy link/frame) ####################################### -->

  <link name="point_cloud">

    <inertial>
      <mass value="0" />
      <origin xyz="0 0 0" rpy="0 0 0"/>
      <inertia ixx="0" ixy="0" ixz="0" iyy="0" iyz="0" izz="0" />
    </inertial>

    <visual>
      <origin xyz="0 0 0" rpy="0 0 0"/>
      <geometry>
        <sphere radius="0.01"/>
      </geometry>
      <material name="green"/>
    </visual>

    <collision>
      <origin xyz="0 0 0" rpy="0 0 0"/>
      <geometry>
        <sphere radius="0.1"/>
      </geometry>
    </collision>
    
  </link>

<!-- ############################## Chassis to Point cloud  ####################################### -->

  <joint name="point_cloud_joint" type="fixed">
    <axis xyz="0 0 0" />
    <origin xyz="0.15 0 0.05" rpy="4.712389 0 4.712389"/>
    <parent link="chassis"/>
    <child link="point_cloud"/>
  </joint>


</robot>